Celery Task Exception: {{ exception_type | safe }} {{ sender | safe }}
